Traceback (most recent call last):
  File "server.py", line 8, in <module>
    print mysql.query_db("SELECT * FROM users")
  File "/Users/jianzhang/Dropbox/Dojo/Python/Flask_MySQL/mysqlconnection.py", line 22, in query_db
    result = self.db.session.execute(text(query), data)
  File "/Users/jianzhang/Dropbox/Dojo/Python/myEnvironment/py2flaskenv/lib/python2.7/site-packages/sqlalchemy/orm/scoping.py", line 157, in do
    return getattr(self.registry(), name)(*args, **kwargs)
  File "/Users/jianzhang/Dropbox/Dojo/Python/myEnvironment/py2flaskenv/lib/python2.7/site-packages/sqlalchemy/orm/session.py", line 1107, in execute
    bind, close_with_result=True).execute(clause, params or {})
  File "/Users/jianzhang/Dropbox/Dojo/Python/myEnvironment/py2flaskenv/lib/python2.7/site-packages/sqlalchemy/engine/base.py", line 945, in execute
    return meth(self, multiparams, params)
  File "/Users/jianzhang/Dropbox/Dojo/Python/myEnvironment/py2flaskenv/lib/python2.7/site-packages/sqlalchemy/sql/elements.py", line 263, in _execute_on_connection
    return connection._execute_clauseelement(self, multiparams, params)
  File "/Users/jianzhang/Dropbox/Dojo/Python/myEnvironment/py2flaskenv/lib/python2.7/site-packages/sqlalchemy/engine/base.py", line 1053, in _execute_clauseelement
    compiled_sql, distilled_params
  File "/Users/jianzhang/Dropbox/Dojo/Python/myEnvironment/py2flaskenv/lib/python2.7/site-packages/sqlalchemy/engine/base.py", line 1189, in _execute_context
    context)
  File "/Users/jianzhang/Dropbox/Dojo/Python/myEnvironment/py2flaskenv/lib/python2.7/site-packages/sqlalchemy/engine/base.py", line 1393, in _handle_dbapi_exception
    exc_info
  File "/Users/jianzhang/Dropbox/Dojo/Python/myEnvironment/py2flaskenv/lib/python2.7/site-packages/sqlalchemy/util/compat.py", line 203, in raise_from_cause
    reraise(type(exception), exception, tb=exc_tb, cause=cause)
  File "/Users/jianzhang/Dropbox/Dojo/Python/myEnvironment/py2flaskenv/lib/python2.7/site-packages/sqlalchemy/engine/base.py", line 1182, in _execute_context
    context)
  File "/Users/jianzhang/Dropbox/Dojo/Python/myEnvironment/py2flaskenv/lib/python2.7/site-packages/sqlalchemy/engine/default.py", line 470, in do_execute
    cursor.execute(statement, parameters)
  File "/Users/jianzhang/Dropbox/Dojo/Python/myEnvironment/py2flaskenv/lib/python2.7/site-packages/MySQLdb/cursors.py", line 205, in execute
    self.errorhandler(self, exc, value)
  File "/Users/jianzhang/Dropbox/Dojo/Python/myEnvironment/py2flaskenv/lib/python2.7/site-packages/MySQLdb/connections.py", line 36, in defaulterrorhandler
    raise errorclass, errorvalue
sqlalchemy.exc.ProgrammingError: (_mysql_exceptions.ProgrammingError) (1146, "Table 'mydb.users' doesn't exist") [SQL: u'SELECT * FROM users']
